<?xml version="1.0" encoding="utf-8"?>
<!-- This URDF was automatically created by SolidWorks to URDF Exporter! Originally created by Stephen Brawner (brawner@gmail.com) 
     Commit Version: 1.6.0-4-g7f85cfe  Build Version: 1.6.7995.38578
     For more information, please see http://wiki.ros.org/sw_urdf_exporter -->
<robot
  name="exo">
  <link
    name="base_link">
    <inertial>
      <origin
        xyz="0.0034138 -0.1254 -0.1285"
        rpy="0 0 0" />
      <mass
        value="3.6015" />
      <inertia
        ixx="0.0035299"
        ixy="-1.1671E-06"
        ixz="9.82E-06"
        iyy="0.0028399"
        iyz="-4.1754E-08"
        izz="0.0061042" />
    </inertial>
    <visual>
      <origin
        xyz="0 0 0"
        rpy="0 0 0" />
      <geometry>
        <mesh
          filename="meshes/base_link.STL" />
      </geometry>
      <material
        name="">
        <color
          rgba="0.89804 0.91765 0.92941 1" />
      </material>
    </visual>
    <collision>
      <origin
        xyz="0 0 0"
        rpy="0 0 0" />
      <geometry>
        <mesh
          filename="meshes/base_link.STL" />
      </geometry>
    </collision>
  </link>
  <link
    name="R_hip_ab_Link">
    <inertial>
      <origin
        xyz="0.062961 0.084633 -0.065069"
        rpy="0 0 0" />
      <mass
        value="0.70297" />
      <inertia
        ixx="0.0015946"
        ixy="-9.7055E-06"
        ixz="9.7056E-06"
        iyy="0.0011657"
        iyz="-0.00045578"
        izz="0.0016625" />
    </inertial>
    <visual>
      <origin
        xyz="0 0 0"
        rpy="0 0 0" />
      <geometry>
        <mesh
          filename="meshes/R_hip_ab_Link.STL" />
      </geometry>
      <material
        name="">
        <color
          rgba="0.89804 0.91765 0.92941 1" />
      </material>
    </visual>
    <collision>
      <origin
        xyz="0 0 0"
        rpy="0 0 0" />
      <geometry>
        <mesh
          filename="meshes/R_hip_ab_Link.STL" />
      </geometry>
    </collision>
  </link>
  <joint
    name="R_hip_ab"
    type="revolute">
    <origin
      xyz="0 0 0"
      rpy="0 0 0" />
    <parent
      link="base_link" />
    <child
      link="R_hip_ab_Link" />
    <axis
      xyz="0 0 1" />
    <limit effort="1000" velocity="10"/>
  </joint>
  <link
    name="R_hip_flex_link">
    <inertial>
      <origin
        xyz="-0.25942 0.0061337 -0.048518"
        rpy="0 0 0" />
      <mass
        value="3.3538" />
      <inertia
        ixx="0.0027427"
        ixy="-5.5939E-07"
        ixz="-1.307E-07"
        iyy="0.0040281"
        iyz="-6.4922E-05"
        izz="0.0059218" />
    </inertial>
    <visual>
      <origin
        xyz="0 0 0"
        rpy="0 0 0" />
      <geometry>
        <mesh
          filename="meshes/R_hip_flex_link.STL" />
      </geometry>
      <material
        name="">
        <color
          rgba="0.89804 0.91765 0.92941 1" />
      </material>
    </visual>
    <collision>
      <origin
        xyz="0 0 0"
        rpy="0 0 0" />
      <geometry>
        <mesh
          filename="meshes/R_hip_flex_link.STL" />
      </geometry>
    </collision>
  </link>
  <joint
    name="R_hip_flex"
    type="revolute">
    <origin
      xyz="0 0.121 0"
      rpy="1.5708 0 0" />
    <parent
      link="R_hip_ab_Link" />
    <child
      link="R_hip_flex_link" />
    <axis
      xyz="0 0 1" />
    <limit effort="1000" velocity="10"/>
  </joint>
  <link
    name="R_knee_link">
    <inertial>
      <origin
        xyz="-0.17215 0.025186 -0.0014145"
        rpy="0 0 0" />
      <mass
        value="0.75992" />
      <inertia
        ixx="0.00047703"
        ixy="9.6405E-09"
        ixz="-6.3773E-09"
        iyy="0.0023194"
        iyz="-4.8885E-05"
        izz="0.0021608" />
    </inertial>
    <visual>
      <origin
        xyz="0 0 0"
        rpy="0 0 0" />
      <geometry>
        <mesh
          filename="meshes/R_knee_link.STL" />
      </geometry>
      <material
        name="">
        <color
          rgba="0.89804 0.91765 0.92941 1" />
      </material>
    </visual>
    <collision>
      <origin
        xyz="0 0 0"
        rpy="0 0 0" />
      <geometry>
        <mesh
          filename="meshes/R_knee_link.STL" />
      </geometry>
    </collision>
  </link>
  <joint
    name="R_knee"
    type="revolute">
    <origin
      xyz="-0.543 0 0"
      rpy="0 0 0" />
    <parent
      link="R_hip_flex_link" />
    <child
      link="R_knee_link" />
    <axis
      xyz="0 0 1" />
    <limit effort="1000" velocity="10"/>
  </joint>
</robot>