<?xml version="1.0" encoding="utf-8"?>
<!-- This URDF was automatically created by SolidWorks to URDF Exporter! Originally created by Stephen Brawner (brawner@gmail.com) 
     Commit Version: 1.6.0-1-g15f4949  Build Version: 1.6.7594.29634
     For more information, please see http://wiki.ros.org/sw_urdf_exporter -->
<robot
  name="Robot">
  <link
    name="base_link">
    <inertial>
      <origin
        xyz="1.7188E-06 0.00038112 0.042746"
        rpy="0 0 0" />
      <mass
        value="0.4964" />
      <inertia
        ixx="0.0005605"
        ixy="-6.2277E-08"
        ixz="-8.4793E-08"
        iyy="0.00056863"
        iyz="6.7147E-06"
        izz="0.00084808" />
    </inertial>
    <visual>
      <origin
        xyz="0 0 0"
        rpy="0 0 0" />
      <geometry>
        <mesh
          filename="./meshes/base_link.STL" />
      </geometry>
      <material
        name="">
        <color
          rgba="1 1 1 1" />
      </material>
    </visual>
    <collision>
      <origin
        xyz="0 0 0"
        rpy="0 0 0" />
      <geometry>
        <mesh
          filename="./meshes/base_link.STL" />
      </geometry>
    </collision>
  </link>
  <link
    name="first_Link">
    <inertial>
      <origin
        xyz="0.001485 1.6346E-05 0.041156"
        rpy="0 0 0" />
      <mass
        value="0.2866" />
      <inertia
        ixx="0.0002524"
        ixy="-1.5091E-07"
        ixz="5.1051E-05"
        iyy="0.00027843"
        iyz="5.2341E-07"
        izz="0.00032172" />
    </inertial>
    <visual>
      <origin
        xyz="0 0 0"
        rpy="0 0 0" />
      <geometry>
        <mesh
          filename="./meshes/first_Link.STL" />
      </geometry>
      <material
        name="">
        <color
          rgba="1 1 1 1" />
      </material>
    </visual>
    <collision>
      <origin
        xyz="0 0 0"
        rpy="0 0 0" />
      <geometry>
        <mesh
          filename="./meshes/first_Link.STL" />
      </geometry>
    </collision>
  </link>
  <joint
    name="first_Jiont"
    type="revolute">
    <origin
      xyz="0 0 0.1081"
      rpy="0 0 0" />
    <parent
      link="base_link" />
    <child
      link="first_Link" />
    <axis
      xyz="0 0 1" />
    <limit effort="1000" velocity="10"/>
  </joint>
  <link
    name="second_Link">
    <inertial>
      <origin
        xyz="0.13642 0.11743 -0.073962"
        rpy="0 0 0" />
      <mass
        value="0.38699" />
      <inertia
        ixx="0.00058886"
        ixy="-0.00031716"
        ixz="-2.3479E-12"
        iyy="0.00068428"
        iyz="6.1764E-12"
        izz="0.00096504" />
    </inertial>
    <visual>
      <origin
        xyz="0 0 0"
        rpy="0 0 0" />
      <geometry>
        <mesh
          filename="./meshes/second_Link.STL" />
      </geometry>
      <material
        name="">
        <color
          rgba="1 1 1 1" />
      </material>
    </visual>
    <collision>
      <origin
        xyz="0 0 0"
        rpy="0 0 0" />
      <geometry>
        <mesh
          filename="./meshes/second_Link.STL" />
      </geometry>
    </collision>
  </link>
  <joint
    name="second_Jiont"
    type="revolute">
    <origin
      xyz="0 0 0.045"
      rpy="1.5708 0 1.5798" />
    <parent
      link="first_Link" />
    <child
      link="second_Link" />
    <axis
      xyz="0 0 1" />
    <limit effort="1000" velocity="10"/>
  </joint>
  <link
    name="third_Link">
    <inertial>
      <origin
        xyz="0.040143 -0.010289 -0.0011322"
        rpy="0 0 0" />
      <mass
        value="0.41859" />
      <inertia
        ixx="0.00042493"
        ixy="0.00016263"
        ixz="-2.0388E-06"
        iyy="0.0010198"
        iyz="4.6529E-07"
        izz="0.0010942" />
    </inertial>
    <visual>
      <origin
        xyz="0 0 0"
        rpy="0 0 0" />
      <geometry>
        <mesh
          filename="./meshes/third_Link.STL" />
      </geometry>
      <material
        name="">
        <color
          rgba="1 1 1 1" />
      </material>
    </visual>
    <collision>
      <origin
        xyz="0 0 0"
        rpy="0 0 0" />
      <geometry>
        <mesh
          filename="./meshes/third_Link.STL" />
      </geometry>
    </collision>
  </link>
  <joint
    name="third_Joint"
    type="revolute">
    <origin
      xyz="0.27284 0.23486 0.005"
      rpy="0 0 0" />
    <parent
      link="second_Link" />
    <child
      link="third_Link" />
    <axis
      xyz="0 0 1" />
    <limit effort="1000" velocity="10"/>
  </joint>
</robot>